<robot name="irrigation_bot">

  <!-- Base Link -->
  <link name="base_link">
    <visual>
      <geometry>
        <box size="0.5 0.3 0.2"/>
      </geometry>
    </visual>
    <collision>
      <geometry>
        <box size="0.5 0.3 0.2"/>
      </geometry>
    </collision>
    <inertial>
      <mass value="5.0"/>
      <inertia ixx="0.02" ixy="0.0" ixz="0.0" iyy="0.02" iyz="0.0" izz="0.02"/>
    </inertial>
  </link>

  <!-- Wheels -->
  <link name="front_left_wheel">
    <visual><geometry><cylinder radius="0.05" length="0.02"/></geometry></visual>
    <collision><geometry><cylinder radius="0.05" length="0.02"/></geometry></collision>
    <inertial><mass value="1.0"/><inertia ixx="0.001" ixy="0" ixz="0" iyy="0.001" iyz="0" izz="0.001"/></inertial>
  </link>

  <link name="front_right_wheel">
    <visual><geometry><cylinder radius="0.05" length="0.02"/></geometry></visual>
    <collision><geometry><cylinder radius="0.05" length="0.02"/></geometry></collision>
    <inertial><mass value="1.0"/><inertia ixx="0.001" ixy="0" ixz="0" iyy="0.001" iyz="0" izz="0.001"/></inertial>
  </link>

  <link name="rear_left_wheel">
    <visual><geometry><cylinder radius="0.05" length="0.02"/></geometry></visual>
    <collision><geometry><cylinder radius="0.05" length="0.02"/></geometry></collision>
    <inertial><mass value="1.0"/><inertia ixx="0.001" ixy="0" ixz="0" iyy="0.001" iyz="0" izz="0.001"/></inertial>
  </link>

  <link name="rear_right_wheel">
    <visual><geometry><cylinder radius="0.05" length="0.02"/></geometry></visual>
    <collision><geometry><cylinder radius="0.05" length="0.02"/></geometry></collision>
    <inertial><mass value="1.0"/><inertia ixx="0.001" ixy="0" ixz="0" iyy="0.001" iyz="0" izz="0.001"/></inertial>
  </link>

  <!-- Sensors -->
  <link name="lidar_link">
    <visual>
      <geometry>
        <cylinder radius="0.05" length="0.04"/>
      </geometry>
      <material name="green">
        <color rgba="0.0 1.0 0.0 1.0"/>
      </material>
    </visual>
    <collision><geometry><cylinder radius="0.05" length="0.04"/></geometry></collision>
    <inertial><mass value="0.5"/><inertia ixx="0.0001" ixy="0" ixz="0" iyy="0.0001" iyz="0" izz="0.0001"/></inertial>
  </link>

  <link name="camera_link">
    <visual>
      <geometry>
        <box size="0.05 0.05 0.05"/>
      </geometry>
      <material name="red">
        <color rgba="1.0 0.2 0.2 1.0"/>
      </material>
    </visual>
    <collision><geometry><box size="0.05 0.05 0.05"/></geometry></collision>
    <inertial><mass value="0.1"/><inertia ixx="0.0001" ixy="0" ixz="0" iyy="0.0001" iyz="0" izz="0.0001"/></inertial>
  </link>

  <!-- Water System -->
  <link name="water_tank">
    <visual><geometry><cylinder radius="0.15" length="0.2"/></geometry></visual>
    <collision><geometry><cylinder radius="0.15" length="0.2"/></geometry></collision>
    <inertial><mass value="2.0"/><inertia ixx="0.01" ixy="0" ixz="0" iyy="0.01" iyz="0" izz="0.01"/></inertial>
  </link>

  <link name="sprayer_link">
    <visual><geometry><cylinder radius="0.02" length="0.1"/></geometry></visual>
    <collision><geometry><cylinder radius="0.02" length="0.1"/></geometry></collision>
    <inertial><mass value="0.2"/><inertia ixx="0.0001" ixy="0" ixz="0" iyy="0.0001" iyz="0" izz="0.0001"/></inertial>
  </link>

  <link name="nozzle_link">
    <visual><geometry><sphere radius="0.01"/></geometry></visual>
    <collision><geometry><sphere radius="0.01"/></geometry></collision>
    <inertial><mass value="0.05"/><inertia ixx="0.00001" ixy="0" ixz="0" iyy="0.00001" iyz="0" izz="0.00001"/></inertial>
  </link>

  <!-- Joints -->
  <joint name="front_left_wheel_joint" type="continuous">
    <parent link="base_link"/>
    <child link="front_left_wheel"/>
    <origin xyz="0.2 0.15 -0.1" rpy="-1.5708 0 0"/>
    <axis xyz="0 0 1"/>
  </joint>

  <joint name="front_right_wheel_joint" type="continuous">
    <parent link="base_link"/>
    <child link="front_right_wheel"/>
    <origin xyz="0.2 -0.15 -0.1" rpy="-1.5708 0 0"/>
    <axis xyz="0 0 1"/>
  </joint>

  <joint name="rear_left_wheel_joint" type="continuous">
    <parent link="base_link"/>
    <child link="rear_left_wheel"/>
    <origin xyz="-0.2 0.15 -0.1" rpy="-1.5708 0 0"/>
    <axis xyz="0 0 1"/>
  </joint>

  <joint name="rear_right_wheel_joint" type="continuous">
    <parent link="base_link"/>
    <child link="rear_right_wheel"/>
    <origin xyz="-0.2 -0.15 -0.1" rpy="-1.5708 0 0"/>
    <axis xyz="0 0 1"/>
  </joint>

  <joint name="lidar_joint" type="fixed">
    <parent link="base_link"/>
    <child link="lidar_link"/>
    <origin xyz="0.2 0 0.12"/>
  </joint>

  <joint name="camera_joint" type="fixed">
    <parent link="base_link"/>
    <child link="camera_link"/>
    <origin xyz="0.24 0 0" rpy="0 0.3 0"/>
  </joint>

  <joint name="water_tank_joint" type="fixed">
    <parent link="base_link"/>
    <child link="water_tank"/>
    <origin xyz="0 0 0.2"/>
  </joint>

  <joint name="sprayer_joint" type="fixed">
    <parent link="base_link"/>
    <child link="sprayer_link"/>
    <origin xyz="0.2 0 -0.15" rpy="0 1.5708 0"/>
  </joint>

  <joint name="nozzle_joint" type="fixed">
    <parent link="sprayer_link"/>
    <child link="nozzle_link"/>
    <origin xyz="0 0 0.06"/>
  </joint>

  <!-- Gazebo Plugins -->
  <gazebo>
    <plugin name="differential_drive_controller" filename="libgazebo_ros_diff_drive.so">
      <left_joint>front_left_wheel_joint rear_left_wheel_joint</left_joint>
      <right_joint>front_right_wheel_joint rear_right_wheel_joint</right_joint>
      <wheel_separation>0.3</wheel_separation>
      <wheel_diameter>0.1</wheel_diameter>
      <max_wheel_torque>20</max_wheel_torque>
      <max_wheel_acceleration>1.0</max_wheel_acceleration>
      <publish_odom>true</publish_odom>
      <publish_odom_tf>true</publish_odom_tf>
      <publish_wheel_tf>true</publish_wheel_tf>
      <odometry_frame>odom</odometry_frame>
      <robot_base_frame>base_link</robot_base_frame>
    </plugin>
  </gazebo>

  <gazebo reference="lidar_link">
    <sensor type="ray" name="lidar_sensor">
      <pose>0 0 0 0 0 0</pose>
      <update_rate>10</update_rate>
      <ray>
        <scan>
          <horizontal>
            <samples>360</samples>
            <resolution>1</resolution>
            <min_angle>-3.14159</min_angle>
            <max_angle>3.14159</max_angle>
          </horizontal>
        </scan>
        <range>
          <min>0.1</min>
          <max>10.0</max>
          <resolution>0.01</resolution>
        </range>
        <noise>
          <type>gaussian</type>
          <mean>0.0</mean>
          <stddev>0.01</stddev>
        </noise>
      </ray>
      <plugin name="lidar_controller" filename="libgazebo_ros_ray_sensor.so">
        <ros>
          <namespace>/irrigation_bot</namespace>
          <remapping>~/out:=scan</remapping>
        </ros>
        <output_type>sensor_msgs/LaserScan</output_type>
        <frame_name>lidar_link</frame_name>
      </plugin>
    </sensor>
    <material>Gazebo/Green</material>
  </gazebo>

  <gazebo reference="camera_link">
    <sensor type="camera" name="camera_sensor">
      <update_rate>30.0</update_rate>
      <camera>
        <horizontal_fov>1.3962634</horizontal_fov>
        <image><width>640</width><height>480</height><format>R8G8B8</format></image>
        <clip><near>0.02</near><far>300</far></clip>
        <noise><type>gaussian</type><mean>0.0</mean><stddev>0.007</stddev></noise>
      </camera>
      <plugin name="camera_controller" filename="libgazebo_ros_camera.so">
        <ros>
          <namespace>/irrigation_bot</namespace>
          <remapping>image_raw:=image</remapping>
          <remapping>camera_info:=camera_info</remapping>
        </ros>
        <frame_name>camera_link</frame_name>
      </plugin>
    </sensor>
    <material>Gazebo/RedGlow</material>
  </gazebo>

</robot>
